Workbook

Sheet Dashboard
A1: Dashboard ejecutivo - Madurez del SGPDP para Empresas del Sector Comercio
A2: Modelo SMARTCIDI | LOPDP Ecuador | 10 dimensiones | evidencia, criticidad, bloqueantes y plan de acción
A4: Madurez global ponderada | B4: =IFERROR(SUMPRODUCT(Dimensiones!B4:B13,Dimensiones!F4:F13)/SUM(Dimensiones!B4:B13),0) -> 0 | D4: Dimensión | E4: Peso | F4: Score | G4: Nivel | H4: Brechas A/C
A5: Cobertura de evaluación | B5: =IFERROR(SUM(Dimensiones!D4:D13)/SUM(Dimensiones!C4:C13),0) -> 0 | D5: =Dimensiones!A4 -> Gobierno y responsabilidad proactiva | E5: =Dimensiones!B4 -> 0.12 | F5: =Dimensiones!F4 -> 0 | G5: =Dimensiones!G4 -> Sin evaluación suficiente | H5: =Dimensiones!H4 -> 0
A6: Nivel teórico numérico | B6: =IF(B4<0.4,1,IF(B4<0.6,2,IF(B4<0.75,3,IF(B4<0.9,4,5)))) -> 1 | D6: =Dimensiones!A5 -> Inventario, RAT, finalidades y legitimación | E6: =Dimensiones!B5 -> 0.14 | F6: =Dimensiones!F5 -> 0 | G6: =Dimensiones!G5 -> Sin evaluación suficiente | H6: =Dimensiones!H5 -> 0
A7: Bloqueantes abiertos | B7: =COUNTIFS(ASSESSMENT!$Q:$Q,"Sí",ASSESSMENT!$M:$M,"<3",ASSESSMENT!$K:$K,">=1") -> 0 | D7: =Dimensiones!A6 -> Transparencia e información al titular | E7: =Dimensiones!B6 -> 0.08 | F7: =Dimensiones!F6 -> 0 | G7: =Dimensiones!G6 -> Sin evaluación suficiente | H7: =Dimensiones!H6 -> 0
A8: Brechas críticas | B8: =COUNTIFS(ASSESSMENT!$P:$P,"Crítico") -> 0 | D8: =Dimensiones!A7 -> Derechos de titulares | E8: =Dimensiones!B7 -> 0.08 | F8: =Dimensiones!F7 -> 0 | G8: =Dimensiones!G7 -> Sin evaluación suficiente | H8: =Dimensiones!H7 -> 0
A9: Brechas altas | B9: =COUNTIFS(ASSESSMENT!$P:$P,"Alto") -> 0 | D9: =Dimensiones!A8 -> Procesos críticos de comercio y ciclo de vida de datos | E9: =Dimensiones!B8 -> 0.1 | F9: =Dimensiones!F8 -> 0 | G9: =Dimensiones!G8 -> Sin evaluación suficiente | H9: =Dimensiones!H8 -> 0
A10: Evidencia insuficiente en controles críticos | B10: =COUNTIFS(ASSESSMENT!$J:$J,">=4",ASSESSMENT!$L:$L,"<2",ASSESSMENT!$I:$I,"Sí",ASSESSMENT!$K:$K,">=1") -> 0 | D10: =Dimensiones!A9 -> Encargados, proveedores y transferencias | E10: =Dimensiones!B9 -> 0.1 | F10: =Dimensiones!F9 -> 0 | G10: =Dimensiones!G9 -> Sin evaluación suficiente | H10: =Dimensiones!H9 -> 0
A11: Nivel final ajustado | B11: =IF(B5<0.6,0,MIN(B6,IF(B7>0,2,5),IF(B10>0,3,5))) -> 0 | D11: =Dimensiones!A10 -> Seguridad de datos personales | E11: =Dimensiones!B10 -> 0.14 | F11: =Dimensiones!F10 -> 0 | G11: =Dimensiones!G10 -> Sin evaluación suficiente | H11: =Dimensiones!H10 -> 0
A12: Resultado ejecutivo | B12: =IF(B11=0,"Sin evaluación suficiente",IF(B11=1,"Nivel 1 - Inicial / Reactivo",IF(B11=2,"Nivel 2 - Básico / Repetible",IF(B11=3,"Nivel 3 - Definido / Documentado",IF(B11=4,"Nivel 4 - Gestionado / Demostrable","Nivel 5 - Optimizado / Mejora continua"))))) -> Sin evaluación suficiente | D12: =Dimensiones!A11 -> Incidentes y vulneraciones | E12: =Dimensiones!B11 -> 0.08 | F12: =Dimensiones!F11 -> 0 | G12: =Dimensiones!G11 -> Sin evaluación suficiente | H12: =Dimensiones!H11 -> 0
D13: =Dimensiones!A12 -> Riesgos, EIPD, LIA y privacidad desde el diseño | E13: =Dimensiones!B12 -> 0.11 | F13: =Dimensiones!F12 -> 0 | G13: =Dimensiones!G12 -> Sin evaluación suficiente | H13: =Dimensiones!H12 -> 0
A14: Antes de aplicar: completar 'Perfil Comercio' y revisar 'Guía Aplicación Comercio'. El resultado final se ajusta por cobertura, evidencia y bloqueantes; no debe interpretarse como certificación legal. | D14: Capacitación, cultura, auditoría y mejora continua | E14: 0.05 | F14: =Dimensiones!F13 -> 0 | G14: =Dimensiones!G13 -> Sin evaluación suficiente | H14: =Dimensiones!H13 -> 0

Sheet ASSESSMENT
A1: Matriz de Madurez del Sistema de Gestión de Protección de Datos Personales - Sector Comercio Ecuador
A2: Versión borrador técnico-consultivo | Aplicable a empresas de comercio minorista, mayorista, e-commerce u omnicanal | Evaluación 1-5 con evidencia
A3: Uso didáctico: completar 'Perfil Comercio' y revisar la hoja 'Guía Aplicación Comercio'. Completar Aplica, Nivel asignado, Nivel evidencia, hallazgos y plan; el modelo calcula madurez, brechas y riesgo.
A4: Metodología resumida | B4: Aplica=Sí entra al cálculo; Aplica=No se excluye. Criticidad pondera el control. Nivel asignado mide madurez observada. Nivel evidencia limita el resultado. Nivel efectivo=MIN(Nivel asignado, Evidencia+1). Riesgo=(5-Nivel efectivo)×Criticidad.
A5: Recomendación de uso | B5: Para una empresa comercial, validar mínimo: clientes y prospectos, tiendas/puntos de venta, POS y facturación, e-commerce si aplica, pagos, CRM/marketing, fidelización, logística/entregas, proveedores, RR. HH., seguridad e incidentes.
A6: ID | B6: Dimensión | C6: Peso Dimensión | D6: Control / Subdimensión | E6: Pregunta de evaluación | F6: Criterio para evaluar madurez | G6: Evidencia solicitada | H6: Responsable / área a entrevistar | I6: Aplica | J6: Criticidad (1-5) | K6: Nivel asignado (1-5) | L6: Nivel evidencia (0-4) | M6: Nivel efectivo | N6: Score ponderado | O6: Base ponderada | P6: Riesgo de brecha | Q6: Bloqueante de madurez | R6: Estado actual / hallazgo | S6: Brecha identificada | T6: Acción recomendada | U6: Prioridad sugerida | V6: Responsable sugerido | W6: Plazo sugerido | X6: Evidencia de cierre | Y6: Estado del plan | Z6: Observaciones
A7: 1 | B7: Gobierno y responsabilidad proactiva | C7: 0.12 | D7: Política de protección de datos personales para la empresa | E7: ¿Existe una política interna de protección de datos personales aprobada, comunicada y adaptada a la operación comercial de la empresa? | F7: La política está aprobada, vigente, asigna roles y contempla clientes, prospectos, colaboradores, proveedores, puntos de venta, canales digitales, CRM, e-commerce si aplica y se revisa periódicamente. | G7: Política aprobada, acta de aprobación, control de versión, evidencia de comunicación interna. | H7: Gerencia / Cumplimiento / DPO | I7: Sí | J7: 5 | M7: =IF(I7="No","N/A",IF(OR(K7="",L7=""),"",MIN(K7,L7+1))) | N7: =IF(OR(I7="No",M7="",M7="N/A"),0,(M7/5)*J7) -> 0 | O7: =IF(I7="Sí",J7,0) -> 5 | P7: =IF(I7="No","No aplica",IF(M7="","Pendiente",IF((5-M7)*J7>=15,"Crítico",IF((5-M7)*J7>=9,"Alto",IF((5-M7)*J7>=5,"Medio","Bajo"))))) -> Pendiente | Q7: Sí | T7: Aprobar o actualizar la política interna, comunicarla formalmente y definir revisión anual. | U7: =IF(P7="Crítico","Crítica",IF(P7="Alto","Alta",IF(P7="Medio","Media",IF(P7="Bajo","Baja","Pendiente")))) -> Pendiente | W7: =IF(U7="Crítica","30 días",IF(U7="Alta","60 días",IF(U7="Media","90 días",IF(U7="Baja","180 días","Por definir")))) -> Por definir | Y7: Pendiente
A8: 2 | B8: Gobierno y responsabilidad proactiva | C8: 0.12 | D8: Roles, responsabilidades y sponsor ejecutivo | E8: ¿Están definidos los responsables internos de protección de datos por área/proceso? | F8: Existen responsables, sponsor ejecutivo y responsabilidades documentadas para procesos críticos. | G8: Matriz RACI, actas de designación, organigrama, perfiles de responsabilidad. | H8: Gerencia / Talento Humano / DPO | I8: Sí | J8: 5 | M8: =IF(I8="No","N/A",IF(OR(K8="",L8=""),"",MIN(K8,L8+1))) | N8: =IF(OR(I8="No",M8="",M8="N/A"),0,(M8/5)*J8) -> 0 | O8: =IF(I8="Sí",J8,0) -> 5 | P8: =IF(I8="No","No aplica",IF(M8="","Pendiente",IF((5-M8)*J8>=15,"Crítico",IF((5-M8)*J8>=9,"Alto",IF((5-M8)*J8>=5,"Medio","Bajo"))))) -> Pendiente | Q8: Sí | T8: Definir responsables internos por proceso y formalizar su rol con soporte de gerencia. | U8: =IF(P8="Crítico","Crítica",IF(P8="Alto","Alta",IF(P8="Medio","Media",IF(P8="Bajo","Baja","Pendiente")))) -> Pendiente | W8: =IF(U8="Crítica","30 días",IF(U8="Alta","60 días",IF(U8="Media","90 días",IF(U8="Baja","180 días","Por definir")))) -> Por definir | Y8: Pendiente
A9: 3 | B9: Gobierno y responsabilidad proactiva | C9: 0.12 | D9: Evaluación de aplicabilidad y designación del DPD | E9: ¿La empresa ha evaluado y documentado si está obligada a designar Delegado de Protección de Datos y, cuando corresponde, la designación está formalizada? | F9: Existe análisis documentado de aplicabilidad; si corresponde designación, el DPD está formalmente nombrado, registrado y cuenta con canal de contacto y acceso a dirección. | G9: Análisis de aplicabilidad, nombramiento/registro si corresponde, contrato o alcance, canal de contacto, informes del DPD. | H9: Gerencia / Legal / Privacidad | I9: Sí | J9: 4 | M9: =IF(I9="No","N/A",IF(OR(K9="",L9=""),"",MIN(K9,L9+1))) | N9: =IF(OR(I9="No",M9="",M9="N/A"),0,(M9/5)*J9) -> 0 | O9: =IF(I9="Sí",J9,0) -> 4 | P9: =IF(I9="No","No aplica",IF(M9="","Pendiente",IF((5-M9)*J9>=15,"Crítico",IF((5-M9)*J9>=9,"Alto",IF((5-M9)*J9>=5,"Medio","Bajo"))))) -> Pendiente | Q9: No | T9: Documentar la evaluación de aplicabilidad del DPD y, si corresponde, formalizar nombramiento, registro, canal y alcance. | U9: =IF(P9="Crítico","Crítica",IF(P9="Alto","Alta",IF(P9="Medio","Media",IF(P9="Bajo","Baja","Pendiente")))) -> Pendiente | W9: =IF(U9="Crítica","30 días",IF(U9="Alta","60 días",IF(U9="Media","90 días",IF(U9="Baja","180 días","Por definir")))) -> Por definir | Y9: Pendiente
A10: 4 | B10: Gobierno y responsabilidad proactiva | C10: 0.12 | D10: Independencia, recursos y seguimiento del DPD cuando aplique | E10: ¿Cuando existe DPD, la empresa garantiza independencia, acceso a dirección, recursos y evidencia de seguimiento de sus recomendaciones? | F10: La función mantiene independencia y segregación respecto de decisiones sobre fines y medios del tratamiento; existe acceso a alta dirección y trazabilidad de recomendaciones. | G10: Actas, agenda, matriz de recomendaciones, reportes de seguimiento, evidencia de escalamiento. | H10: Gerencia / DPD / Legal / Áreas | I10: Sí | J10: 4 | M10: =IF(I10="No","N/A",IF(OR(K10="",L10=""),"",MIN(K10,L10+1))) | N10: =IF(OR(I10="No",M10="",M10="N/A"),0,(M10/5)*J10) -> 0 | O10: =IF(I10="Sí",J10,0) -> 4 | P10: =IF(I10="No","No aplica",IF(M10="","Pendiente",IF((5-M10)*J10>=15,"Crítico",IF((5-M10)*J10>=9,"Alto",IF((5-M10)*J10>=5,"Medio","Bajo"))))) -> Pendiente | Q10: No | T10: Formalizar independencia, línea de reporte, recursos y seguimiento de recomendaciones del DPD cuando aplique. | U10: =IF(P10="Crítico","Crítica",IF(P10="Alto","Alta",IF(P10="Medio","Media",IF(P10="Bajo","Baja","Pendiente")))) -> Pendiente | W10: =IF(U10="Crítica","30 días",IF(U10="Alta","60 días",IF(U10="Media","90 días",IF(U10="Baja","180 días","Por definir")))) -> Por definir | Y10: Pendiente
A11: 5 | B11: Gobierno y responsabilidad proactiva | C11: 0.12 | D11: Mapa de obligaciones y base normativa aplicable | E11: ¿La organización tiene identificadas las obligaciones LOPDP aplicables a su operación? | F11: Existe un mapa normativo que vincula obligaciones con procesos, controles y evidencias. | G11: Mapa normativo, matriz de cumplimiento, criterios de aplicabilidad, revisión legal-consultiva. | H11: Cumplimiento / Legal / DPO | I11: Sí | J11: 4 | M11: =IF(I11="No","N/A",IF(OR(K11="",L11=""),"",MIN(K11,L11+1))) | N11: =IF(OR(I11="No",M11="",M11="N/A"),0,(M11/5)*J11) -> 0 | O11: =IF(I11="Sí",J11,0) -> 4 | P11: =IF(I11="No","No aplica",IF(M11="","Pendiente",IF((5-M11)*J11>=15,"Crítico",IF((5-M11)*J11>=9,"Alto",IF((5-M11)*J11>=5,"Medio","Bajo"))))) -> Pendiente | Q11: No | T11: Elaborar matriz de obligaciones aplicables y vincularlas con controles internos. | U11: =IF(P11="Crítico","Crítica",IF(P11="Alto","Alta",IF(P11="Medio","Media",IF(P11="Bajo","Baja","Pendiente")))) -> Pendiente | W11: =IF(U11="Crítica","30 días",IF(U11="Alta","60 días",IF(U11="Media","90 días",IF(U11="Baja","180 días","Por definir")))) -> Por definir | Y11: Pendiente
A12: 6 | B12: Gobierno y responsabilidad proactiva | C12: 0.12 | D12: Presupuesto y recursos | E12: ¿Existe asignación de recursos para sostener el sistema de protección de datos? | F12: Se asignan recursos para capacitación, herramientas, seguridad, consultoría, auditoría y mejoras. | G12: Presupuesto, plan anual, aprobaciones, órdenes de compra, cronograma. | H12: Gerencia / Finanzas / TI | I12: Sí | J12: 3 | M12: =IF(I12="No","N/A",IF(OR(K12="",L12=""),"",MIN(K12,L12+1))) | N12: =IF(OR(I12="No",M12="",M12="N/A"),0,(M12/5)*J12) -> 0 | O12: =IF(I12="Sí",J12,0) -> 3 | P12: =IF(I12="No","No aplica",IF(M12="","Pendiente",IF((5-M12)*J12>=15,"Crítico",IF((5-M12)*J12>=9,"Alto",IF((5-M12)*J12>=5,"Medio","Bajo"))))) -> Pendiente | Q12: No | T12: Definir presupuesto proporcional al riesgo para sostener cumplimiento y seguridad. | U12: =IF(P12="Crítico","Crítica",IF(P12="Alto","Alta",IF(P12="Medio","Media",IF(P12="Bajo","Baja","Pendiente")))) -> Pendiente | W12: =IF(U12="Crítica","30 días",IF(U12="Alta","60 días",IF(U12="Media","90 días",IF(U12="Baja","180 días","Por definir")))) -> Por definir | Y12: Pendiente
A13: 7 | B13: Gobierno y responsabilidad proactiva | C13: 0.12 | D13: Gestión documental del SGPDP | E13: ¿Los documentos de protección de datos tienen control de versión, dueño y fecha de revisión? | F13: Documentos controlados, aprobados, versionados y disponibles para responsables internos. | G13: Repositorio, control maestro de documentos, versiones, responsables, historial de cambios. | H13: Cumplimiento / Calidad / DPO | I13: Sí | J13: 3 | M13: =IF(I13="No","N/A",IF(OR(K13="",L13=""),"",MIN(K13,L13+1))) | N13: =IF(OR(I13="No",M13="",M13="N/A"),0,(M13/5)*J13) -> 0 | O13: =IF(I13="Sí",J13,0) -> 3 | P13: =IF(I13="No","No aplica",IF(M13="","Pendiente",IF((5-M13)*J13>=15,"Crítico",IF((5-M13)*J13>=9,"Alto",IF((5-M13)*J13>=5,"Medio","Bajo"))))) -> Pendiente | Q13: No | T13: Crear control maestro documental para políticas, matrices, procedimientos y evidencias. | U13: =IF(P13="Crítico","Crítica",IF(P13="Alto","Alta",IF(P13="Medio","Media",IF(P13="Bajo","Baja","Pendiente")))) -> Pendiente | W13: =IF(U13="Crítica","30 días",IF(U13="Alta","60 días",IF(U13="Media","90 días",IF(U13="Baja","180 días","Por definir")))) -> Por definir | Y13: Pendiente
A14: 8 | B14: Gobierno y responsabilidad proactiva | C14: 0.12 | D14: Indicadores y reportes a dirección | E14: ¿Se reportan indicadores de protección de datos a la alta dirección? | F14: Existen KPIs de incidentes, derechos, capacitación, riesgos, proveedores y avance de acciones. | G14: Dashboard, informes mensuales/trimestrales, actas de revisión por dirección. | H14: DPO / Gerencia / Cumplimiento | I14: Sí | J14: 3 | M14: =IF(I14="No","N/A",IF(OR(K14="",L14=""),"",MIN(K14,L14+1))) | N14: =IF(OR(I14="No",M14="",M14="N/A"),0,(M14/5)*J14) -> 0 | O14: =IF(I14="Sí",J14,0) -> 3 | P14: =IF(I14="No","No aplica",IF(M14="","Pendiente",IF((5-M14)*J14>=15,"Crítico",IF((5-M14)*J14>=9,"Alto",IF((5-M14)*J14>=5,"Medio","Bajo"))))) -> Pendiente | Q14: No | T14: Definir indicadores mínimos y reportarlos periódicamente a dirección. | U14: =IF(P14="Crítico","Crítica",IF(P14="Alto","Alta",IF(P14="Medio","Media",IF(P14="Bajo","Baja","Pendiente")))) -> Pendiente | W14: =IF(U14="Crítica","30 días",IF(U14="Alta","60 días",IF(U14="Media","90 días",IF(U14="Baja","180 días","Por definir")))) -> Por definir | Y14: Pendiente
A15: 9 | B15: Inventario, RAT, finalidades y legitimación | C15: 0.14 | D15: Inventario de tratamientos de la empresa | E15: ¿Existe un inventario actualizado de tratamientos de datos personales por proceso comercial y corporativo? | F15: El inventario identifica captación y registro de clientes, ventas/POS, facturación, e-commerce si aplica, pagos, marketing/CRM, servicio al cliente, logística, RR. HH., proveedores y seguridad. | G15: Inventario de datos, mapa de procesos, fichas de tratamiento. | H15: DPO / Procesos / Áreas | I15: Sí | J15: 5 | M15: =IF(I15="No","N/A",IF(OR(K15="",L15=""),"",MIN(K15,L15+1))) | N15: =IF(OR(I15="No",M15="",M15="N/A"),0,(M15/5)*J15) -> 0 | O15: =IF(I15="Sí",J15,0) -> 5 | P15: =IF(I15="No","No aplica",IF(M15="","Pendiente",IF((5-M15)*J15>=15,"Crítico",IF((5-M15)*J15>=9,"Alto",IF((5-M15)*J15>=5,"Medio","Bajo"))))) -> Pendiente | Q15: Sí | T15: Levantar o actualizar inventario de tratamientos con dueños por proceso. | U15: =IF(P15="Crítico","Crítica",IF(P15="Alto","Alta",IF(P15="Medio","Media",IF(P15="Bajo","Baja","Pendiente")))) -> Pendiente | W15: =IF(U15="Crítica","30 días",IF(U15="Alta","60 días",IF(U15="Media","90 días",IF(U15="Baja","180 días","Por definir")))) -> Por definir | Y15: Pendiente
A16: 10 | B16: Inventario, RAT, finalidades y legitimación | C16: 0.14 | D16: Registro de Actividades de Tratamiento (RAT) | E16: ¿Existe un RAT actualizado y alineado con los procesos reales de la empresa? | F16: El RAT contiene actividades, finalidades, categorías de titulares, datos, destinatarios, conservación, medidas de seguridad, encargados y transferencias cuando correspondan. | G16: RAT, control de cambios, evidencia de validación por áreas. | H16: DPO / Cumplimiento / Áreas | I16: Sí | J16: 5 | M16: =IF(I16="No","N/A",IF(OR(K16="",L16=""),"",MIN(K16,L16+1))) | N16: =IF(OR(I16="No",M16="",M16="N/A"),0,(M16/5)*J16) -> 0 | O16: =IF(I16="Sí",J16,0) -> 5 | P16: =IF(I16="No","No aplica",IF(M16="","Pendiente",IF((5-M16)*J16>=15,"Crítico",IF((5-M16)*J16>=9,"Alto",IF((5-M16)*J16>=5,"Medio","Bajo"))))) -> Pendiente | Q16: Sí | T16: Construir o actualizar RAT con base en procesos reales y evidencia de validación. | U16: =IF(P16="Crítico","Crítica",IF(P16="Alto","Alta",IF(P16="Medio","Media",IF(P16="Bajo","Baja","Pendiente")))) -> Pendiente | W16: =IF(U16="Crítica","30 días",IF(U16="Alta","60 días",IF(U16="Media","90 días",IF(U16="Baja","180 días","Por definir")))) -> Por definir | Y16: Pendiente
A17: 11 | B17: Inventario, RAT, finalidades y legitimación | C17: 0.14 | D17: Finalidades específicas y documentadas | E17: ¿Cada tratamiento tiene finalidades claras, específicas y documentadas? | F17: Las finalidades son explícitas, legítimas, no genéricas y se reflejan en avisos y procesos. | G17: RAT, avisos de privacidad, formularios, procedimientos, bases de legitimación. | H17: DPO / Legal / Áreas | I17: Sí | J17: 5 | M17: =IF(I17="No","N/A",IF(OR(K17="",L17=""),"",MIN(K17,L17+1))) | N17: =IF(OR(I17="No",M17="",M17="N/A"),0,(M17/5)*J17) -> 0 | O17: =IF(I17="Sí",J17,0) -> 5 | P17: =IF(I17="No","No aplica",IF(M17="","Pendiente",IF((5-M17)*J17>=15,"Crítico",IF((5-M17)*J17>=9,"Alto",IF((5-M17)*J17>=5,"Medio","Bajo"))))) -> Pendiente | Q17: Sí | T17: Depurar finalidades y eliminar descripciones genéricas o incompatibles. | U17: =IF(P17="Crítico","Crítica",IF(P17="Alto","Alta",IF(P17="Medio","Media",IF(P17="Bajo","Baja","Pendiente")))) -> Pendiente | W17: =IF(U17="Crítica","30 días",IF(U17="Alta","60 días",IF(U17="Media","90 días",IF(U17="Baja","180 días","Por definir")))) -> Por definir | Y17: Pendiente
A18: 12 | B18: Inventario, RAT, finalidades y legitimación | C18: 0.14 | D18: Base de legitimación por tratamiento | E18: ¿Cada tratamiento tiene identificada y justificada su base de legitimación? | F18: La base se asigna por tratamiento, con racionales y criterios de aplicabilidad. | G18: Matriz de bases, consentimientos, contratos, obligación legal, LIA cuando aplique. | H18: DPO / Legal / Áreas | I18: Sí | J18: 5 | M18: =IF(I18="No","N/A",IF(OR(K18="",L18=""),"",MIN(K18,L18+1))) | N18: =IF(OR(I18="No",M18="",M18="N/A"),0,(M18/5)*J18) -> 0 | O18: =IF(I18="Sí",J18,0) -> 5 | P18: =IF(I18="No","No aplica",IF(M18="","Pendiente",IF((5-M18)*J18>=15,"Crítico",IF((5-M18)*J18>=9,"Alto",IF((5-M18)*J18>=5,"Medio","Bajo"))))) -> Pendiente | Q18: Sí | T18: Validar bases de legitimación por proceso y documentar rationale. | U18: =IF(P18="Crítico","Crítica",IF(P18="Alto","Alta",IF(P18="Medio","Media",IF(P18="Bajo","Baja","Pendiente")))) -> Pendiente | W18: =IF(U18="Crítica","30 días",IF(U18="Alta","60 días",IF(U18="Media","90 días",IF(U18="Baja","180 días","Por definir")))) -> Por definir | Y18: Pendiente
... A86: 80 | B86: Capacitación, cultura, auditoría y mejora continua | C86: 0.05 | D86: Mejora continua y revisión por dirección | E86: ¿La alta dirección revisa periódicamente resultados, riesgos y madurez del SGPDP? | F86: Se presentan indicadores, brechas, riesgos residuales y decisiones de mejora. | G86: Informe anual/semestral, actas, hoja de ruta, KPIs. | H86: Gerencia / DPO / Cumplimiento | I86: Sí | J86: 4 | M86: =IF(I86="No","N/A",IF(OR(K86="",L86=""),"",MIN(K86,L86+1))) | N86: =IF(OR(I86="No",M86="",M86="N/A"),0,(M86/5)*J86) -> 0 | O86: =IF(I86="Sí",J86,0) -> 4 | P86: =IF(I86="No","No aplica",IF(M86="","Pendiente",IF((5-M86)*J86>=15,"Crítico",IF((5-M86)*J86>=9,"Alto",IF((5-M86)*J86>=5,"Medio","Bajo"))))) -> Pendiente | Q86: No | T86: Establecer revisión por dirección y hoja de ruta anual. | U86: =IF(P86="Crítico","Crítica",IF(P86="Alto","Alta",IF(P86="Medio","Media",IF(P86="Bajo","Baja","Pendiente")))) -> Pendiente | W86: =IF(U86="Crítica","30 días",IF(U86="Alta","60 días",IF(U86="Media","90 días",IF(U86="Baja","180 días","Por definir")))) -> Por definir | Y86: Pendiente

Sheet Dimensiones
A1: Resultados por dimensión del SGPDP
A3: Dimensión | B3: Peso | C3: Ítems aplicables | D3: Ítems evaluados | E3: % cobertura | F3: Score dimensión | G3: Nivel dimensión | H3: Brechas críticas/altas | I3: Observación automática
A4: Gobierno y responsabilidad proactiva | B4: 0.12 | C4: =COUNTIFS(ASSESSMENT!$B:$B,A4,ASSESSMENT!$I:$I,"Sí") -> 8 | D4: =COUNTIFS(ASSESSMENT!$B:$B,A4,ASSESSMENT!$I:$I,"Sí",ASSESSMENT!$K:$K,">=1") -> 0 | E4: =IFERROR(D4/C4,0) -> 0 | F4: =IFERROR(SUMIFS(ASSESSMENT!$N:$N,ASSESSMENT!$B:$B,A4)/SUMIFS(ASSESSMENT!$O:$O,ASSESSMENT!$B:$B,A4),0) -> 0 | G4: =IF(E4<0.6,"Sin evaluación suficiente",IF(F4<0.4,"Nivel 1 - Inicial",IF(F4<0.6,"Nivel 2 - Básico",IF(F4<0.75,"Nivel 3 - Definido",IF(F4<0.9,"Nivel 4 - Gestionado","Nivel 5 - Optimizado"))))) -> Sin evaluación suficiente | H4: =COUNTIFS(ASSESSMENT!$B:$B,A4,ASSESSMENT!$P:$P,"Crítico")+COUNTIFS(ASSESSMENT!$B:$B,A4,ASSESSMENT!$P:$P,"Alto") -> 0 | I4: =IF(E4<0.6,"Completar evaluación",IF(H4>0,"Cerrar brechas prioritarias","Mantener y mejorar")) -> Completar evaluación
A5: Inventario, RAT, finalidades y legitimación | B5: 0.14 | C5: =COUNTIFS(ASSESSMENT!$B:$B,A5,ASSESSMENT!$I:$I,"Sí") -> 8 | D5: =COUNTIFS(ASSESSMENT!$B:$B,A5,ASSESSMENT!$I:$I,"Sí",ASSESSMENT!$K:$K,">=1") -> 0 | E5: =IFERROR(D5/C5,0) -> 0 | F5: =IFERROR(SUMIFS(ASSESSMENT!$N:$N,ASSESSMENT!$B:$B,A5)/SUMIFS(ASSESSMENT!$O:$O,ASSESSMENT!$B:$B,A5),0) -> 0 | G5: =IF(E5<0.6,"Sin evaluación suficiente",IF(F5<0.4,"Nivel 1 - Inicial",IF(F5<0.6,"Nivel 2 - Básico",IF(F5<0.75,"Nivel 3 - Definido",IF(F5<0.9,"Nivel 4 - Gestionado","Nivel 5 - Optimizado"))))) -> Sin evaluación suficiente | H5: =COUNTIFS(ASSESSMENT!$B:$B,A5,ASSESSMENT!$P:$P,"Crítico")+COUNTIFS(ASSESSMENT!$B:$B,A5,ASSESSMENT!$P:$P,"Alto") -> 0 | I5: =IF(E5<0.6,"Completar evaluación",IF(H5>0,"Cerrar brechas prioritarias","Mantener y mejorar")) -> Completar evaluación
A6: Transparencia e información al titular | B6: 0.08 | C6: =COUNTIFS(ASSESSMENT!$B:$B,A6,ASSESSMENT!$I:$I,"Sí") -> 8 | D6: =COUNTIFS(ASSESSMENT!$B:$B,A6,ASSESSMENT!$I:$I,"Sí",ASSESSMENT!$K:$K,">=1") -> 0 | E6: =IFERROR(D6/C6,0) -> 0 | F6: =IFERROR(SUMIFS(ASSESSMENT!$N:$N,ASSESSMENT!$B:$B,A6)/SUMIFS(ASSESSMENT!$O:$O,ASSESSMENT!$B:$B,A6),0) -> 0 | G6: =IF(E6<0.6,"Sin evaluación suficiente",IF(F6<0.4,"Nivel 1 - Inicial",IF(F6<0.6,"Nivel 2 - Básico",IF(F6<0.75,"Nivel 3 - Definido",IF(F6<0.9,"Nivel 4 - Gestionado","Nivel 5 - Optimizado"))))) -> Sin evaluación suficiente | H6: =COUNTIFS(ASSESSMENT!$B:$B,A6,ASSESSMENT!$P:$P,"Crítico")+COUNTIFS(ASSESSMENT!$B:$B,A6,ASSESSMENT!$P:$P,"Alto") -> 0 | I6: =IF(E6<0.6,"Completar evaluación",IF(H6>0,"Cerrar brechas prioritarias","Mantener y mejorar")) -> Completar evaluación
A7: Derechos de titulares | B7: 0.08 | C7: =COUNTIFS(ASSESSMENT!$B:$B,A7,ASSESSMENT!$I:$I,"Sí") -> 8 | D7: =COUNTIFS(ASSESSMENT!$B:$B,A7,ASSESSMENT!$I:$I,"Sí",ASSESSMENT!$K:$K,">=1") -> 0 | E7: =IFERROR(D7/C7,0) -> 0 | F7: =IFERROR(SUMIFS(ASSESSMENT!$N:$N,ASSESSMENT!$B:$B,A7)/SUMIFS(ASSESSMENT!$O:$O,ASSESSMENT!$B:$B,A7),0) -> 0 | G7: =IF(E7<0.6,"Sin evaluación suficiente",IF(F7<0.4,"Nivel 1 - Inicial",IF(F7<0.6,"Nivel 2 - Básico",IF(F7<0.75,"Nivel 3 - Definido",IF(F7<0.9,"Nivel 4 - Gestionado","Nivel 5 - Optimizado"))))) -> Sin evaluación suficiente | H7: =COUNTIFS(ASSESSMENT!$B:$B,A7,ASSESSMENT!$P:$P,"Crítico")+COUNTIFS(ASSESSMENT!$B:$B,A7,ASSESSMENT!$P:$P,"Alto") -> 0 | I7: =IF(E7<0.6,"Completar evaluación",IF(H7>0,"Cerrar brechas prioritarias","Mantener y mejorar")) -> Completar evaluación
A8: Procesos críticos de comercio y ciclo de vida de datos | B8: 0.1 | C8: =COUNTIFS(ASSESSMENT!$B:$B,A8,ASSESSMENT!$I:$I,"Sí") -> 8 | D8: =COUNTIFS(ASSESSMENT!$B:$B,A8,ASSESSMENT!$I:$I,"Sí",ASSESSMENT!$K:$K,">=1") -> 0 | E8: =IFERROR(D8/C8,0) -> 0 | F8: =IFERROR(SUMIFS(ASSESSMENT!$N:$N,ASSESSMENT!$B:$B,A8)/SUMIFS(ASSESSMENT!$O:$O,ASSESSMENT!$B:$B,A8),0) -> 0 | G8: =IF(E8<0.6,"Sin evaluación suficiente",IF(F8<0.4,"Nivel 1 - Inicial",IF(F8<0.6,"Nivel 2 - Básico",IF(F8<0.75,"Nivel 3 - Definido",IF(F8<0.9,"Nivel 4 - Gestionado","Nivel 5 - Optimizado"))))) -> Sin evaluación suficiente | H8: =COUNTIFS(ASSESSMENT!$B:$B,A8,ASSESSMENT!$P:$P,"Crítico")+COUNTIFS(ASSESSMENT!$B:$B,A8,ASSESSMENT!$P:$P,"Alto") -> 0 | I8: =IF(E8<0.6,"Completar evaluación",IF(H8>0,"Cerrar brechas prioritarias","Mantener y mejorar")) -> Completar evaluación
A9: Encargados, proveedores y transferencias | B9: 0.1 | C9: =COUNTIFS(ASSESSMENT!$B:$B,A9,ASSESSMENT!$I:$I,"Sí") -> 8 | D9: =COUNTIFS(ASSESSMENT!$B:$B,A9,ASSESSMENT!$I:$I,"Sí",ASSESSMENT!$K:$K,">=1") -> 0 | E9: =IFERROR(D9/C9,0) -> 0 | F9: =IFERROR(SUMIFS(ASSESSMENT!$N:$N,ASSESSMENT!$B:$B,A9)/SUMIFS(ASSESSMENT!$O:$O,ASSESSMENT!$B:$B,A9),0) -> 0 | G9: =IF(E9<0.6,"Sin evaluación suficiente",IF(F9<0.4,"Nivel 1 - Inicial",IF(F9<0.6,"Nivel 2 - Básico",IF(F9<0.75,"Nivel 3 - Definido",IF(F9<0.9,"Nivel 4 - Gestionado","Nivel 5 - Optimizado"))))) -> Sin evaluación suficiente | H9: =COUNTIFS(ASSESSMENT!$B:$B,A9,ASSESSMENT!$P:$P,"Crítico")+COUNTIFS(ASSESSMENT!$B:$B,A9,ASSESSMENT!$P:$P,"Alto") -> 0 | I9: =IF(E9<0.6,"Completar evaluación",IF(H9>0,"Cerrar brechas prioritarias","Mantener y mejorar")) -> Completar evaluación
A10: Seguridad de datos personales | B10: 0.14 | C10: =COUNTIFS(ASSESSMENT!$B:$B,A10,ASSESSMENT!$I:$I,"Sí") -> 8 | D10: =COUNTIFS(ASSESSMENT!$B:$B,A10,ASSESSMENT!$I:$I,"Sí",ASSESSMENT!$K:$K,">=1") -> 0 | E10: =IFERROR(D10/C10,0) -> 0 | F10: =IFERROR(SUMIFS(ASSESSMENT!$N:$N,ASSESSMENT!$B:$B,A10)/SUMIFS(ASSESSMENT!$O:$O,ASSESSMENT!$B:$B,A10),0) -> 0 | G10: =IF(E10<0.6,"Sin evaluación suficiente",IF(F10<0.4,"Nivel 1 - Inicial",IF(F10<0.6,"Nivel 2 - Básico",IF(F10<0.75,"Nivel 3 - Definido",IF(F10<0.9,"Nivel 4 - Gestionado","Nivel 5 - Optimizado"))))) -> Sin evaluación suficiente | H10: =COUNTIFS(ASSESSMENT!$B:$B,A10,ASSESSMENT!$P:$P,"Crítico")+COUNTIFS(ASSESSMENT!$B:$B,A10,ASSESSMENT!$P:$P,"Alto") -> 0 | I10: =IF(E10<0.6,"Completar evaluación",IF(H10>0,"Cerrar brechas prioritarias","Mantener y mejorar")) -> Completar evaluación
A11: Incidentes y vulneraciones | B11: 0.08 | C11: =COUNTIFS(ASSESSMENT!$B:$B,A11,ASSESSMENT!$I:$I,"Sí") -> 8 | D11: =COUNTIFS(ASSESSMENT!$B:$B,A11,ASSESSMENT!$I:$I,"Sí",ASSESSMENT!$K:$K,">=1") -> 0 | E11: =IFERROR(D11/C11,0) -> 0 | F11: =IFERROR(SUMIFS(ASSESSMENT!$N:$N,ASSESSMENT!$B:$B,A11)/SUMIFS(ASSESSMENT!$O:$O,ASSESSMENT!$B:$B,A11),0) -> 0 | G11: =IF(E11<0.6,"Sin evaluación suficiente",IF(F11<0.4,"Nivel 1 - Inicial",IF(F11<0.6,"Nivel 2 - Básico",IF(F11<0.75,"Nivel 3 - Definido",IF(F11<0.9,"Nivel 4 - Gestionado","Nivel 5 - Optimizado"))))) -> Sin evaluación suficiente | H11: =COUNTIFS(ASSESSMENT!$B:$B,A11,ASSESSMENT!$P:$P,"Crítico")+COUNTIFS(ASSESSMENT!$B:$B,A11,ASSESSMENT!$P:$P,"Alto") -> 0 | I11: =IF(E11<0.6,"Completar evaluación",IF(H11>0,"Cerrar brechas prioritarias","Mantener y mejorar")) -> Completar evaluación
A12: Riesgos, EIPD, LIA y privacidad desde el diseño | B12: 0.11 | C12: =COUNTIFS(ASSESSMENT!$B:$B,A12,ASSESSMENT!$I:$I,"Sí") -> 8 | D12: =COUNTIFS(ASSESSMENT!$B:$B,A12,ASSESSMENT!$I:$I,"Sí",ASSESSMENT!$K:$K,">=1") -> 0 | E12: =IFERROR(D12/C12,0) -> 0 | F12: =IFERROR(SUMIFS(ASSESSMENT!$N:$N,ASSESSMENT!$B:$B,A12)/SUMIFS(ASSESSMENT!$O:$O,ASSESSMENT!$B:$B,A12),0) -> 0 | G12: =IF(E12<0.6,"Sin evaluación suficiente",IF(F12<0.4,"Nivel 1 - Inicial",IF(F12<0.6,"Nivel 2 - Básico",IF(F12<0.75,"Nivel 3 - Definido",IF(F12<0.9,"Nivel 4 - Gestionado","Nivel 5 - Optimizado"))))) -> Sin evaluación suficiente | H12: =COUNTIFS(ASSESSMENT!$B:$B,A12,ASSESSMENT!$P:$P,"Crítico")+COUNTIFS(ASSESSMENT!$B:$B,A12,ASSESSMENT!$P:$P,"Alto") -> 0 | I12: =IF(E12<0.6,"Completar evaluación",IF(H12>0,"Cerrar brechas prioritarias","Mantener y mejorar")) -> Completar evaluación
A13: Capacitación, cultura, auditoría y mejora continua | B13: 0.05 | C13: =COUNTIFS(ASSESSMENT!$B:$B,A13,ASSESSMENT!$I:$I,"Sí") -> 8 | D13: =COUNTIFS(ASSESSMENT!$B:$B,A13,ASSESSMENT!$I:$I,"Sí",ASSESSMENT!$K:$K,">=1") -> 0 | E13: =IFERROR(D13/C13,0) -> 0 | F13: =IFERROR(SUMIFS(ASSESSMENT!$N:$N,ASSESSMENT!$B:$B,A13)/SUMIFS(ASSESSMENT!$O:$O,ASSESSMENT!$B:$B,A13),0) -> 0 | G13: =IF(E13<0.6,"Sin evaluación suficiente",IF(F13<0.4,"Nivel 1 - Inicial",IF(F13<0.6,"Nivel 2 - Básico",IF(F13<0.75,"Nivel 3 - Definido",IF(F13<0.9,"Nivel 4 - Gestionado","Nivel 5 - Optimizado"))))) -> Sin evaluación suficiente | H13: =COUNTIFS(ASSESSMENT!$B:$B,A13,ASSESSMENT!$P:$P,"Crítico")+COUNTIFS(ASSESSMENT!$B:$B,A13,ASSESSMENT!$P:$P,"Alto") -> 0 | I13: =IF(E13<0.6,"Completar evaluación",IF(H13>0,"Cerrar brechas prioritarias","Mantener y mejorar")) -> Completar evaluación

Sheet Niveles de Madurez
A1: Criterios de madurez del SGPDP
A3: Nivel | B3: Nombre | C3: Criterio operativo | D3: Evidencia típica | E3: Qué demuestra | F3: Rango global
A4: 1 | B4: Inicial / Reactivo | C4: No existe o se gestiona informalmente; depende de personas y no de un sistema. | D4: Entrevista verbal, prácticas no documentadas. | E4: Baja capacidad de demostrar cumplimiento. | F4: 0% - 39%
A5: 2 | B5: Básico / Repetible | C5: Existen prácticas aisladas o documentos iniciales, pero no están integrados ni son uniformes. | D5: Documentos parciales, formatos iniciales, acciones puntuales. | E5: Cumplimiento incipiente con brechas estructurales. | F5: 40% - 59%
A6: 3 | B6: Definido / Documentado | C6: Existen políticas, matrices, procedimientos y responsables definidos. | D6: Documentos aprobados, matrices, registros parciales. | E6: Base de cumplimiento organizada pero con evidencia operativa limitada. | F6: 60% - 74%
A7: 4 | B7: Gestionado / Demostrable | C7: El sistema se aplica, se revisa, tiene seguimiento, métricas y evidencias periódicas. | D7: Registros, actas, indicadores, auditorías internas, seguimiento de brechas. | E7: Cumplimiento operativo y demostrable. | F7: 75% - 89%
A8: 5 | B8: Optimizado / Mejora continua | C8: El sistema está integrado a gobierno, riesgos, seguridad, proveedores, proyectos y mejora continua. | D8: KPIs, revisión por dirección, DPO activo, auditorías, simulacros, mejoras recurrentes. | E8: Madurez avanzada y resiliente. | F8: 90% - 100%

Sheet Plan de Acción
A1: Plan de acción derivado de la Matriz SGPDP
A2: Use filtros para priorizar Crítico/Alto y estados Pendiente/En progreso. Esta hoja replica los ítems evaluados para seguimiento.
A4: ID | B4: Dimensión | C4: Control | D4: Riesgo | E4: Prioridad | F4: Acción recomendada | G4: Responsable | H4: Plazo | I4: Evidencia de cierre | J4: Estado | K4: Observaciones
A5: =ASSESSMENT!A7 -> 1 | B5: =ASSESSMENT!B7 -> Gobierno y responsabilidad proactiva | C5: =ASSESSMENT!D7 -> Política de protección de datos personales para la empresa | D5: =ASSESSMENT!P7 -> Pendiente | E5: =ASSESSMENT!U7 -> Pendiente | F5: =ASSESSMENT!T7 -> Aprobar o actualizar la política interna, comunicarla formalmente y definir revisión anual. | G5: =ASSESSMENT!V7 -> 0 | H5: =ASSESSMENT!W7 -> Por definir | I5: =ASSESSMENT!X7 -> 0 | J5: =ASSESSMENT!Y7 -> Pendiente | K5: =ASSESSMENT!Z7 -> 0
A6: =ASSESSMENT!A8 -> 2 | B6: =ASSESSMENT!B8 -> Gobierno y responsabilidad proactiva | C6: =ASSESSMENT!D8 -> Roles, responsabilidades y sponsor ejecutivo | D6: =ASSESSMENT!P8 -> Pendiente | E6: =ASSESSMENT!U8 -> Pendiente | F6: =ASSESSMENT!T8 -> Definir responsables internos por proceso y formalizar su rol con soporte de gerencia. | G6: =ASSESSMENT!V8 -> 0 | H6: =ASSESSMENT!W8 -> Por definir | I6: =ASSESSMENT!X8 -> 0 | J6: =ASSESSMENT!Y8 -> Pendiente | K6: =ASSESSMENT!Z8 -> 0
A7: =ASSESSMENT!A9 -> 3 | B7: =ASSESSMENT!B9 -> Gobierno y responsabilidad proactiva | C7: =ASSESSMENT!D9 -> Evaluación de aplicabilidad y designación del DPD | D7: =ASSESSMENT!P9 -> Pendiente | E7: =ASSESSMENT!U9 -> Pendiente | F7: =ASSESSMENT!T9 -> Documentar la evaluación de aplicabilidad del DPD y, si corresponde, formalizar nombramiento, registro, canal y alcance. | G7: =ASSESSMENT!V9 -> 0 | H7: =ASSESSMENT!W9 -> Por definir | I7: =ASSESSMENT!X9 -> 0 | J7: =ASSESSMENT!Y9 -> Pendiente | K7: =ASSESSMENT!Z9 -> 0
A8: =ASSESSMENT!A10 -> 4 | B8: =ASSESSMENT!B10 -> Gobierno y responsabilidad proactiva | C8: =ASSESSMENT!D10 -> Independencia, recursos y seguimiento del DPD cuando aplique | D8: =ASSESSMENT!P10 -> Pendiente | E8: =ASSESSMENT!U10 -> Pendiente | F8: =ASSESSMENT!T10 -> Formalizar independencia, línea de reporte, recursos y seguimiento de recomendaciones del DPD cuando aplique. | G8: =ASSESSMENT!V10 -> 0 | H8: =ASSESSMENT!W10 -> Por definir | I8: =ASSESSMENT!X10 -> 0 | J8: =ASSESSMENT!Y10 -> Pendiente | K8: =ASSESSMENT!Z10 -> 0
A9: =ASSESSMENT!A11 -> 5 | B9: =ASSESSMENT!B11 -> Gobierno y responsabilidad proactiva | C9: =ASSESSMENT!D11 -> Mapa de obligaciones y base normativa aplicable | D9: =ASSESSMENT!P11 -> Pendiente | E9: =ASSESSMENT!U11 -> Pendiente | F9: =ASSESSMENT!T11 -> Elaborar matriz de obligaciones aplicables y vincularlas con controles internos. | G9: =ASSESSMENT!V11 -> 0 | H9: =ASSESSMENT!W11 -> Por definir | I9: =ASSESSMENT!X11 -> 0 | J9: =ASSESSMENT!Y11 -> Pendiente | K9: =ASSESSMENT!Z11 -> 0
A10: =ASSESSMENT!A12 -> 6 | B10: =ASSESSMENT!B12 -> Gobierno y responsabilidad proactiva | C10: =ASSESSMENT!D12 -> Presupuesto y recursos | D10: =ASSESSMENT!P12 -> Pendiente | E10: =ASSESSMENT!U12 -> Pendiente | F10: =ASSESSMENT!T12 -> Definir presupuesto proporcional al riesgo para sostener cumplimiento y seguridad. | G10: =ASSESSMENT!V12 -> 0 | H10: =ASSESSMENT!W12 -> Por definir | I10: =ASSESSMENT!X12 -> 0 | J10: =ASSESSMENT!Y12 -> Pendiente | K10: =ASSESSMENT!Z12 -> 0
A11: =ASSESSMENT!A13 -> 7 | B11: =ASSESSMENT!B13 -> Gobierno y responsabilidad proactiva | C11: =ASSESSMENT!D13 -> Gestión documental del SGPDP | D11: =ASSESSMENT!P13 -> Pendiente | E11: =ASSESSMENT!U13 -> Pendiente | F11: =ASSESSMENT!T13 -> Crear control maestro documental para políticas, matrices, procedimientos y evidencias. | G11: =ASSESSMENT!V13 -> 0 | H11: =ASSESSMENT!W13 -> Por definir | I11: =ASSESSMENT!X13 -> 0 | J11: =ASSESSMENT!Y13 -> Pendiente | K11: =ASSESSMENT!Z13 -> 0
A12: =ASSESSMENT!A14 -> 8 | B12: =ASSESSMENT!B14 -> Gobierno y responsabilidad proactiva | C12: =ASSESSMENT!D14 -> Indicadores y reportes a dirección | D12: =ASSESSMENT!P14 -> Pendiente | E12: =ASSESSMENT!U14 -> Pendiente | F12: =ASSESSMENT!T14 -> Definir indicadores mínimos y reportarlos periódicamente a dirección. | G12: =ASSESSMENT!V14 -> 0 | H12: =ASSESSMENT!W14 -> Por definir | I12: =ASSESSMENT!X14 -> 0 | J12: =ASSESSMENT!Y14 -> Pendiente | K12: =ASSESSMENT!Z14 -> 0
A13: =ASSESSMENT!A15 -> 9 | B13: =ASSESSMENT!B15 -> Inventario, RAT, finalidades y legitimación | C13: =ASSESSMENT!D15 -> Inventario de tratamientos de la empresa | D13: =ASSESSMENT!P15 -> Pendiente | E13: =ASSESSMENT!U15 -> Pendiente | F13: =ASSESSMENT!T15 -> Levantar o actualizar inventario de tratamientos con dueños por proceso. | G13: =ASSESSMENT!V15 -> 0 | H13: =ASSESSMENT!W15 -> Por definir | I13: =ASSESSMENT!X15 -> 0 | J13: =ASSESSMENT!Y15 -> Pendiente | K13: =ASSESSMENT!Z15 -> 0
A14: =ASSESSMENT!A16 -> 10 | B14: =ASSESSMENT!B16 -> Inventario, RAT, finalidades y legitimación | C14: =ASSESSMENT!D16 -> Registro de Actividades de Tratamiento (RAT) | D14: =ASSESSMENT!P16 -> Pendiente | E14: =ASSESSMENT!U16 -> Pendiente | F14: =ASSESSMENT!T16 -> Construir o actualizar RAT con base en procesos reales y evidencia de validación. | G14: =ASSESSMENT!V16 -> 0 | H14: =ASSESSMENT!W16 -> Por definir | I14: =ASSESSMENT!X16 -> 0 | J14: =ASSESSMENT!Y16 -> Pendiente | K14: =ASSESSMENT!Z16 -> 0
A15: =ASSESSMENT!A17 -> 11 | B15: =ASSESSMENT!B17 -> Inventario, RAT, finalidades y legitimación | C15: =ASSESSMENT!D17 -> Finalidades específicas y documentadas | D15: =ASSESSMENT!P17 -> Pendiente | E15: =ASSESSMENT!U17 -> Pendiente | F15: =ASSESSMENT!T17 -> Depurar finalidades y eliminar descripciones genéricas o incompatibles. | G15: =ASSESSMENT!V17 -> 0 | H15: =ASSESSMENT!W17 -> Por definir | I15: =ASSESSMENT!X17 -> 0 | J15: =ASSESSMENT!Y17 -> Pendiente | K15: =ASSESSMENT!Z17 -> 0
A16: =ASSESSMENT!A18 -> 12 | B16: =ASSESSMENT!B18 -> Inventario, RAT, finalidades y legitimación | C16: =ASSESSMENT!D18 -> Base de legitimación por tratamiento | D16: =ASSESSMENT!P18 -> Pendiente | E16: =ASSESSMENT!U18 -> Pendiente | F16: =ASSESSMENT!T18 -> Validar bases de legitimación por proceso y documentar rationale. | G16: =ASSESSMENT!V18 -> 0 | H16: =ASSESSMENT!W18 -> Por definir | I16: =ASSESSMENT!X18 -> 0 | J16: =ASSESSMENT!Y18 -> Pendiente | K16: =ASSESSMENT!Z18 -> 0
... A84: =ASSESSMENT!A86 -> 80 | B84: =ASSESSMENT!B86 -> Capacitación, cultura, auditoría y mejora continua | C84: =ASSESSMENT!D86 -> Mejora continua y revisión por dirección | D84: =ASSESSMENT!P86 -> Pendiente | E84: =ASSESSMENT!U86 -> Pendiente | F84: =ASSESSMENT!T86 -> Establecer revisión por dirección y hoja de ruta anual. | G84: =ASSESSMENT!V86 -> 0 | H84: =ASSESSMENT!W86 -> Por definir | I84: =ASSESSMENT!X86 -> 0 | J84: =ASSESSMENT!Y86 -> Pendiente | K84: =ASSESSMENT!Z86 -> 0

Sheet Catálogos
A1: Catálogos del modelo
A2: Aplica | B2: Sí | C2: No
A3: Nivel asignado (1-5) | B3: 1 | C3: 2 | D3: 3
B4: 4 | C4: 5
A5: Nivel evidencia (0-4) | B5: 0 | C5: 1 | D5: 2
B6: 3 | C6: 4
A7: Bloqueante | B7: Sí | C7: No
A8: Prioridad | B8: Crítica | C8: Alta | D8: Media
B9: Baja | C9: Pendiente
A10: Estado del plan | B10: Pendiente | C10: En proceso | D10: Cerrado
B11: No iniciado | C11: No aplica
A12: Criterio evidencia 0 | B12: Sin evidencia / declaración verbal
A13: Criterio evidencia 1 | B13: Evidencia informal: correo, captura, práctica no formalizada
A14: Criterio evidencia 2 | B14: Evidencia documental: política, matriz, procedimiento, contrato
A15: Criterio evidencia 3 | B15: Evidencia operativa: registros, bitácoras, actas, solicitudes atendidas
A16: Criterio evidencia 4 | B16: Evidencia gestionada: indicadores, auditoría, revisión y mejora

Sheet Base Normativa
A1: Base normativa y técnica de referencia para empresas del sector comercio
A2: Referencia | B2: Uso en el assessment | C2: Naturaleza | D2: Dimensiones vinculadas | E2: Nota para el consultor
A3: Constitución de la República del Ecuador | B3: Derecho a la protección de datos personales, acceso y decisión sobre información personal. | C3: Base constitucional | D3: Todas | E3: Usar como fundamento general de derechos.
A4: Ley Orgánica de Protección de Datos Personales | B4: Principios, derechos, obligaciones del responsable/encargado, seguridad, RAT, DPD, incidentes y régimen aplicable. | C4: Obligación legal | D4: Todas | E4: Validar siempre con versión oficial vigente.
A5: Reglamento General a la LOPDP | B5: Desarrollo de medidas, derechos, seguridad, evaluación de impacto, privacidad desde el diseño, roles y evidencias. | C5: Obligación reglamentaria | D5: Gobierno, derechos, seguridad, riesgos | E5: Aplicar con enfoque proporcional al tamaño, canales, volumen y riesgo de la empresa.
A6: Normativa secundaria y guías de la SPDP | B6: Criterios sobre riesgos, EIPD, privacidad desde el diseño, DPD, contratos, transferencias e interés legítimo cuando aplique. | C6: Normativa / guía oficial | D6: Riesgos, DPD, proveedores, contratos | E6: Diferenciar obligación jurídica, normativa secundaria, guía y buena práctica.
A7: Ley Orgánica de Defensa del Consumidor | B7: Contexto de relación con clientes, información, atención, reclamos, garantías y prácticas comerciales cuando corresponda. | C7: Normativa relacionada / cuando aplique | D7: Transparencia, atención, procesos comerciales | E7: No sustituye el análisis específico de protección de datos; validar aplicabilidad al negocio.
A8: Ley de Comercio Electrónico, Firmas Electrónicas y Mensajes de Datos | B8: Contexto para contratación, mensajes de datos, transacciones y canales electrónicos cuando corresponda. | C8: Normativa relacionada / cuando aplique | D8: Canales digitales, e-commerce, evidencias | E8: Validar especialmente en ventas y contratación por medios electrónicos.
A9: Normativa tributaria, societaria, laboral y de conservación aplicable | B9: Puede justificar determinados datos, documentos y plazos de conservación en facturación, contabilidad, contratos y RR. HH. | C9: Obligación sectorial/transversal según actividad | D9: Conservación, RR. HH., procesos comerciales | E9: No fijar plazos genéricos: documentar fundamento específico por categoría documental.
A10: Buenas prácticas de seguridad de la información | B10: Accesos, MFA, endpoints, respaldos, registros, cifrado, nube, proveedores, vulnerabilidades e incidentes. | C10: Buena práctica técnica | D10: Seguridad, incidentes, proveedores | E10: Usar de forma proporcional; no presentar como certificación si no existe.
A11: Modelo de madurez SMARTCIDI | B11: Evalúa madurez 1-5 combinando nivel asignado, evidencia, criticidad, bloqueantes y plan de acción. | C11: Metodología consultiva | D11: Todas | E11: Sirve para diagnóstico, priorización y hoja de ruta; no equivale a certificación legal.

Sheet Guía Aplicación Comercio
A1: Guía de Aplicación del Assessment SGPDP para Empresas del Sector Comercio
A2: Objetivo | B2: Medir el nivel de madurez del Sistema de Gestión de Protección de Datos Personales de una empresa comercial ecuatoriana, considerando LOPDP, riesgos, evidencia y operación real en canales físicos y digitales.
A3: Cómo aplicar | B3: 1) Completar 'Perfil Comercio'. 2) Confirmar alcance: matriz, tiendas/sucursales, POS, ERP, CRM, e-commerce, pagos, logística, proveedores y canales. 3) Entrevistar áreas. 4) Solicitar evidencias. 5) Completar Aplica, Nivel asignado y Nivel evidencia. 6) Revisar Dashboard y Plan de Acción.
A5: Campo | B5: Qué significa | C5: Valores permitidos | D5: Cómo decidir | E5: Ejemplo comercio | F5: Impacto en el cálculo
A6: Aplica | B6: Determina si el control entra o no al cálculo. | C6: Sí / No | D6: Marcar No solo si el control realmente no corresponde al modelo de negocio. No usar No para ocultar una brecha. En caso de duda, mantener Sí hasta validar. | E6: E-commerce puede ser No en un comercio exclusivamente físico; transferencia internacional solo después de validar nube, SaaS y proveedores. | F6: Si No: se excluye del score y riesgo.
A7: Criticidad | B7: Peso del control dentro de la madurez. No mide cumplimiento, mide importancia. | C7: 1 a 5 | D7: 5 para controles estructurales o de alto riesgo: RAT, derechos, incidentes, seguridad, POS/pagos, e-commerce, proveedores críticos. Ajustar según contexto. | E7: Pagos/POS o e-commerce = 5 cuando aplican; capacitación general = 3. | F7: A mayor criticidad, mayor peso y mayor brecha si el nivel es bajo.
A8: Nivel asignado | B8: Madurez observada del control según entrevista y revisión. | C8: 1 a 5 | D8: 1 no existe; 2 parcial; 3 documentado; 4 aplicado con evidencias; 5 medido y mejorado. | E8: Existe procedimiento de derechos, pero no hay registros de aplicación: nivel 3 como máximo. | F8: Se combina con evidencia para obtener nivel efectivo.
A9: Nivel evidencia | B9: Calidad de la evidencia que respalda el nivel asignado. | C9: 0 a 4 | D9: 0 verbal; 1 informal; 2 documental; 3 operativa; 4 revisada con indicadores/auditoría. | E9: Política aprobada = 2; solicitudes atendidas con registro = 3; indicadores revisados por dirección/DPD = 4. | F9: Limita el nivel efectivo mediante MIN(Nivel asignado, Evidencia+1).
A10: Nivel efectivo | B10: Nivel real reconocido por el modelo después de validar evidencia. | C10: Automático | D10: No se llena manualmente. | E10: Si asigna 5 pero evidencia 2, el nivel efectivo será 3. | F10: Base del score y del riesgo de brecha.
A11: Score ponderado | B11: Puntaje obtenido por el control. | C11: Automático | D11: Fórmula: Nivel efectivo / 5 × Criticidad. | E11: Control crítico de pago/POS con nivel efectivo 3 suma 3 puntos de 5 posibles. | F11: Suma al score de dimensión y global.
A12: Riesgo de brecha | B12: Criticidad de lo que falta para llegar a madurez 5. | C12: Automático | D12: Fórmula conceptual: (5 - Nivel efectivo) × Criticidad. | E12: Procedimiento de incidentes con nivel 1 y criticidad 5 = brecha crítica. | F12: Prioriza acciones del plan.
A13: Bloqueante de madurez | B13: Control que impide declarar una madurez alta si está débil. | C13: Sí / No | D13: Marcar Sí en controles esenciales: RAT, derechos, incidentes, seguridad, gobierno y procesos comerciales críticos. | E13: No tener RAT, procedimiento de derechos, incidentes o controles críticos de seguridad no debe permitir declarar madurez alta. | F13: Dashboard limita el nivel final ajustado.
A15: Escala de madurez | B15: Criterio resumido | C15: Evidencia esperada
A16: Nivel 1 - Inicial / Reactivo | B16: No existe o se gestiona informalmente. | C16: Declaraciones verbales o prácticas aisladas.
A17: Nivel 2 - Básico / Repetible | B17: Existe parcialmente o depende de personas; no está integrado. | C17: Borradores, correos, controles informales.
A18: Nivel 3 - Definido / Documentado | B18: Existe documento, responsable y criterio aprobado. | C18: Políticas, matrices, procedimientos, contratos, registros básicos.
A19: Nivel 4 - Gestionado / Demostrable | B19: Se aplica y se revisa con evidencia periódica. | C19: Actas, bitácoras, solicitudes atendidas, revisiones, reportes.
A20: Nivel 5 - Optimizado / Mejora continua | B20: Se mide, audita, corrige y mejora continuamente. | C20: Indicadores, auditoría, revisión por dirección/DPO, mejoras implementadas.
A22: Reglas prácticas para el consultor | B22: 1) Si el control debería existir y no existe: Aplica=Sí, Nivel=1, Evidencia=0. 2) Si solo hay documento sin uso: nivel máximo sugerido=3. 3) Si hay registros de aplicación: nivel 4. 4) Si hay indicadores y mejora continua: nivel 5. 5) Si no se sabe si aplica, no marcar No hasta validar. 6) En comercios omnicanal revisar coherencia entre tienda física, web/e-commerce, CRM, POS, pagos y logística.
A23: Entregables esperados | B23: Perfil de contexto validado, Dashboard ejecutivo, madurez por dimensión, brechas críticas/altas, bloqueantes, plan de acción 30/60/90/180 días y evidencias requeridas.

Sheet Procesos Comercio
A1: Procesos comerciales sugeridos para revisar durante el assessment
A2: Proceso | B2: Datos personales típicos | C2: Titulares | D2: Riesgos frecuentes | E2: Evidencia a solicitar
A3: Captación, registro y actualización de clientes | B3: Identificación, contacto, preferencias, cuenta de cliente, historial básico, origen del lead. | C3: Prospectos / clientes | D3: Recolección excesiva, origen no trazable, falta de aviso, datos desactualizados. | E3: Formularios, CRM, ficha de cliente, avisos, matrices de datos y bases de legitimación.
A4: Venta presencial, POS y facturación | B4: Identificación cuando corresponde, factura, datos de contacto, compra, comprobantes, vendedor/caja. | C4: Clientes | D4: Exposición en caja, permisos excesivos, impresión innecesaria, exportaciones sin control. | E4: Configuración POS, facturas, perfiles de caja, logs, procedimiento de venta.
A5: E-commerce y cuentas de usuario | B5: Registro, correo/teléfono, credenciales, carrito, pedidos, historial, direcciones, cookies cuando apliquen. | C5: Usuarios / clientes | D5: Campos excesivos, cuentas comprometidas, cookies/trackers sin revisión, integraciones no controladas. | E5: Flujo de registro/checkout, aviso, cookies, logs, integraciones, contrato de plataforma.
A6: Pagos, pasarelas y prevención de fraude | B6: Datos de transacción, referencia de pago, medio de pago, señales antifraude; datos de tarjeta solo según arquitectura. | C6: Clientes | D6: Almacenamiento innecesario, terceros no evaluados, exposición en logs, fraude o accesos indebidos. | E6: Contratos con pasarelas/adquirentes, flujo de pago, configuración, logs, controles antifraude.
A7: CRM, fidelización y marketing | B7: Contacto, historial/segmentos, preferencias, campañas, puntos/beneficios, respuestas. | C7: Prospectos / clientes | D7: Listas sin base, perfilamiento opaco, falta de oposición/baja, reutilización incompatible. | E7: CRM, formularios de fidelización, campañas, preferencias, bajas, consentimientos cuando apliquen.
A8: Servicio al cliente, devoluciones, garantías y reclamos | B8: Identificación, pedido/factura, motivo, contacto, evidencias, tickets y comunicaciones. | C8: Clientes / usuarios | D8: Pedir más datos de los necesarios, revelar historial, mala verificación de identidad. | E8: Tickets, formularios, guiones, procedimiento, registros de verificación y respuestas.
A9: Logística, despacho, entrega y retiro | B9: Nombre, teléfono, dirección, pedido, instrucciones de entrega, evidencia de recepción. | C9: Clientes / destinatarios | D9: Etiquetas visibles, acceso excesivo, couriers sin control, conservación indefinida. | E9: Órdenes de despacho, etiquetas, contratos con couriers, perfiles y comprobantes de entrega.
A10: Talento humano | B10: Expedientes laborales, selección, nómina, afiliaciones, salud ocupacional cuando aplique, accesos. | C10: Colaboradores / postulantes | D10: Acceso excesivo, conservación indefinida, bajas tardías, datos sensibles sin controles. | E10: Expedientes, avisos laborales, confidencialidad, bajas de usuarios, matriz de accesos.
A11: Proveedores y encargados | B11: Datos corporativos y personales; acceso de terceros a CRM, POS, ERP, nube, logística, marketing, soporte. | C11: Clientes / colaboradores / proveedores | D11: Contratos sin cláusulas, soporte sin trazabilidad, subencargados y transferencias no identificadas. | E11: Inventario de proveedores, contratos/DPA, due diligence, SLA y evidencias de seguridad.
A12: Archivo físico/digital y conservación | B12: Facturas, contratos, expedientes, reclamos, RR. HH., pedidos, reportes y respaldos. | C12: Todos los titulares | D12: Acumulación, eliminación insegura, permisos excesivos, duplicados y copias locales. | E12: Tabla de conservación, inventario, políticas de archivo, permisos, actas/certificados de eliminación.
A13: Incidentes y continuidad | B13: Datos afectados por pérdida, acceso indebido, malware, cuenta comprometida, envío erróneo o indisponibilidad. | C13: Todos los titulares | D13: Falta de detección, registro, contención, evaluación de impacto o escalamiento. | E13: Procedimiento, registro de incidentes, simulacros, tickets, lecciones aprendidas y planes de mejora.

Sheet Perfil Comercio
A1: Perfil de contexto y alcance - Empresa del Sector Comercio
A2: Completar antes del assessment. Estas variables ayudan a decidir aplicabilidad, criticidad, entrevistas y evidencias; para estimar esfuerzo, duración y presupuesto utilizar la hoja 'Dimensionamiento Servicios'.
A4: Variable | B4: Qué validar | C4: Respuesta / dato | D4: Riesgo o impacto en el assessment | E4: Evidencia sugerida | F4: Estado
A5: Tipo de comercio | B5: Retail, mayorista, distribuidor, e-commerce, marketplace, franquicia u omnicanal. | D5: Define procesos y canales a evaluar. | E5: RUC/objeto, organigrama, descripción operativa. | F5: Por validar
A6: Número de tiendas / sucursales | B6: Locales, bodegas, centros de distribución y oficinas. | D6: Aumenta dispersión de accesos, CCTV, archivos y usuarios. | E6: Listado de ubicaciones. | F6: Por validar
A7: Número de empleados / usuarios con acceso | B7: Personal propio, temporal y terceros con cuentas. | D7: Dimensiona gestión de identidades, capacitación y bajas. | E7: Nómina y listado de usuarios. | F7: Por validar
A8: Volumen aproximado de clientes activos | B8: Clientes identificados y cuentas registradas. | D8: Influye en escala, riesgo y esfuerzo de derechos/incidentes. | E8: CRM/ERP/POS, reportes. | F8: Por validar
A9: Volumen histórico de registros | B9: Clientes, prospectos, pedidos y facturas conservados. | D9: Afecta conservación, eliminación, riesgo de exposición y migraciones. | E9: Reportes de bases/repositorios. | F9: Por validar
A10: POS / sistema de cajas | B10: Proveedor, arquitectura, usuarios, datos capturados, integración con ERP/CRM. | D10: Proceso crítico en comercio presencial. | E10: Contrato, matriz de accesos, configuración. | F10: Por validar
A11: ERP / facturación / inventario | B11: Sistemas, módulos y datos personales incluidos. | D11: Puede centralizar datos de clientes, personal y proveedores. | E11: Inventario de sistemas y contratos. | F11: Por validar
A12: CRM | B12: Plataforma, finalidades, usuarios, integraciones, marketing y exportaciones. | D12: Alto impacto en prospección, campañas y fidelización. | E12: DPA/contrato, perfiles, flujos. | F12: Por validar
A13: E-commerce / app | B13: Plataforma, cuentas, checkout, pedidos, cookies e integraciones. | D13: Activa controles específicos de canales digitales. | E13: URL, contrato, configuración, mapa de integraciones. | F13: Por validar
A14: Pasarelas / medios de pago | B14: Proveedores, datos visibles/almacenados, tokenización y antifraude. | D14: Flujo de alto riesgo; delimitar responsabilidades y almacenamiento. | E14: Contratos, diagrama de pago, configuración. | F14: Por validar
A15: Programa de fidelización | B15: Puntos, perfil de cliente, preferencias, segmentos y beneficios. | D15: Puede aumentar perfilamiento y reutilización de datos. | E15: Términos, formulario, CRM, reglas del programa. | F15: Por validar
A16: Marketing y automatización | B16: Email/SMS/WhatsApp, audiencias, pixels, listas, plataformas y fuentes. | D16: Requiere trazabilidad de origen, oposición y bases. | E16: Plataformas, campañas, formularios, consentimientos. | F16: Por validar
... A29: Incidentes previos | B29: Pérdida, phishing, cuentas comprometidas, envíos erróneos, malware o fuga. | D29: Ajusta riesgo y priorización del plan de acción. | E29: Registro de incidentes/tickets. | F29: Por validar

Sheet Dimensionamiento
A1: HOJA HISTÓRICA – NO UTILIZAR PARA NUEVAS COTIZACIONES. Use la hoja “Dimensionamiento Servicios” (modelo v1.3).
A2: Herramienta interna SMARTCIDI para estimar el alcance de una consultoría LOPDP en empresas del sector comercio. Complete los campos amarillos; ingrese 0 cuando una categoría numérica haya sido validada y no aplique. El resultado es una estimación comercial basada en escala, complejidad, riesgo, tecnología y madurez; no es una exigencia legal ni sustituye el diagnóstico.
A4: Cobertura de información | B4: =(COUNTA(C20:C30)+COUNTA(C35:C42)+COUNTA(C46:C51)+COUNTA(C55:C61))/32 -> 0 | C4: Índice de complejidad | D4: =IF(OR(B4<0.6,COUNT(C25:C30)=0),"",B70) | E4: Nivel | F4: =IF(OR(B4<0.6,COUNT(C25:C30)=0),"Información insuficiente",IF(D4<=25,"Baja",IF(D4<=50,"Media",IF(D4<=75,"Alta","Muy alta")))) -> Información insuficiente | G4: Esfuerzo central | H4: =IF(OR(B4<0.6,COUNT(C25:C30)=0),"",$C$14+D4*$C$15)
A5: Duración estimada | B5: =IF(OR(OR(B4<0.6,COUNT(C25:C30)=0),$C$11<=0),"",ROUNDUP(H4/$C$11,0)) | C5: Presupuesto objetivo* | D5: =IF(OR(OR(B4<0.6,COUNT(C25:C30)=0),$C$10<=0),"",H4*$C$10*(1+$C$12)*$C$13) | E5: Presupuesto mínimo* | F5: =IF(D5="","",D5*(1-$C$16)) | G5: Presupuesto máximo* | H5: =IF(D5="","",D5*(1+$C$16))
A7: Equipo sugerido | B7: =IF(OR(B4<0.6,COUNT(C25:C30)=0),"Completar información para estimar",IF(D4<=25,"1 consultor líder + apoyo puntual",IF(D4<=50,"1 consultor líder + 1 especialista",IF(D4<=75,"2 consultores / especialistas","Equipo multidisciplinario de 2 a 3+ perfiles")))) -> Completar información para estimar
A8: Alcance sugerido | B8: =IF(OR(B4<0.6,COUNT(C25:C30)=0),"Completar información para estimar",IF(D4<=25,"Assessment + implementación base",IF(D4<=50,"Proyecto estándar de diagnóstico e implementación",IF(D4<=75,"Proyecto ampliado con remediación priorizada","Proyecto complejo por fases / oleadas")))) -> Completar información para estimar
A9: Parámetros comerciales SMARTCIDI (editables)
A10: Tarifa interna referencial (sin impuestos) | B10: USD por hora. Ingresar la tarifa comercial interna de SMARTCIDI antes de impuestos. | C10: 0 | D10: USD/h | H10: Si se deja en 0, el presupuesto no se calcula.
A11: Capacidad asignada al proyecto | B11: Horas efectivas por semana que el equipo puede dedicar a esta consultoría. | C11: 12 | D11: h/semana | H11: Afecta la duración, no el esfuerzo total.
A12: Contingencia del proyecto | B12: Reserva por coordinación, retrabajo, validaciones y hallazgos no previstos. | C12: 0.15 | D12: % | H12: Parámetro comercial interno.
A13: Factor comercial | B13: Ajuste por posicionamiento, complejidad contractual o estrategia comercial. | C13: 1 | D13: factor | H13: 1,00 = sin ajuste.
A14: Horas base | B14: Esfuerzo mínimo para movilización, levantamiento, análisis y cierre. | C14: 40 | D14: horas | H14: Base del modelo.
A15: Horas por punto de complejidad | B15: Pendiente que convierte el índice 0-100 en horas adicionales. | C15: 2.1 | D15: h/punto | H15: Editable con experiencia histórica SMARTCIDI.
A16: Margen del rango presupuestario | B16: Rango inferior/superior respecto del presupuesto objetivo. | C16: 0.1 | D16: % | H16: Permite presentar una banda de negociación.
A18: A. Escala, volumen y estructura operativa
A19: Variable | B19: Qué debe informar la empresa | C19: Respuesta / dato | D19: Unidad / opciones | E19: Score | F19: Peso interno | G19: Aporte | H19: Impacto en el alcance
A20: Número de empleados | B20: Personal propio y terceros recurrentes que participan en la operación. | D20: personas | E20: =IF(C20="","",IF(C20<=20,10,IF(C20<=50,25,IF(C20<=100,45,IF(C20<=250,65,IF(C20<=500,85,100)))))) | F20: 0.3 | G20: =IF(E20="","",E20*F20) | H20: Dimensiona usuarios, capacitación, accesos y número de entrevistas.
A21: Número de sucursales / locales | B21: Tiendas, oficinas, bodegas y centros de distribución con operación propia. | D21: ubicaciones | E21: =IF(C21="","",IF(C21<=1,10,IF(C21<=3,25,IF(C21<=10,50,IF(C21<=25,75,100))))) | F21: 0.2 | G21: =IF(E21="","",E21*F21) | H21: Aumenta dispersión de archivos, CCTV, usuarios y variaciones de proceso.
A22: Número de áreas con tratamiento | B22: Áreas o unidades que recolectan, usan, consultan o conservan datos personales. | D22: áreas | E22: =IF(C22="","",IF(C22<=3,10,IF(C22<=5,25,IF(C22<=8,50,IF(C22<=12,75,100))))) | F22: 0.25 | G22: =IF(E22="","",E22*F22) | H22: Determina entrevistas, responsables y cobertura del levantamiento.
A23: Número de procesos con datos personales | B23: Procesos identificados que involucran datos personales. | D23: procesos | E23: =IF(C23="","",IF(C23<=5,10,IF(C23<=10,30,IF(C23<=20,55,IF(C23<=35,80,100))))) | F23: 0.35 | G23: =IF(E23="","",E23*F23) | H23: Variable directa del esfuerzo para inventario, RAT y evidencias.
A24: Documentación de procesos | B24: Nivel en que los procesos están levantados, documentados y actualizados. | D24: seleccionar | E24: =IF(C24="","",IF(C24="Completa y actualizada",0,IF(C24="Parcialmente documentados",40,IF(C24="Documentación informal",70,IF(C24="No documentados",100,80))))) | F24: 0.2 | G24: =IF(E24="","",E24*F24) | H24: Si no existen procesos documentados, aumenta el esfuerzo de descubrimiento antes del análisis LOPDP.
A25: Clientes activos | B25: Clientes identificados o cuentas activas. | D25: titulares | H25: Parte del volumen total de titulares.
A26: Clientes históricos | B26: Registros históricos conservados de clientes, pedidos o facturación. | D26: titulares | H26: Afecta conservación, archivo y volumen de datos.
A27: Prospectos / leads | B27: Contactos de campañas, formularios, CRM, redes sociales u otros canales. | D27: titulares | H27: Aumenta complejidad de marketing, trazabilidad y oposición.
